<?xml version="1.0" ?>
<!-- =================================================================================== -->
<!-- |    This document was autogenerated by xacro from baxter.urdf.xacro              | -->
<!-- |    EDITING THIS FILE BY HAND IS NOT RECOMMENDED                                 | -->
<!-- =================================================================================== -->
<!-- mcevoy.andy@gmail.com -->
<robot name="baxter" xmlns:xacro="http://www.ros.org/wiki/xacro" xmlns:xi="http://www.w3.org/2001/XInclude">
  <link name="base">
  </link>
  <link name="collision_head_link_1">
    <inertial>
      <mass value="0.0001"/>
      <origin rpy="0 -0 0" xyz="0 0 0"/>
      <inertia ixx="1e-08" ixy="0" ixz="0" iyy="1e-08" iyz="0" izz="1e-08"/>
    </inertial>
    <visual>
      <origin rpy="0 -0 0" xyz="0 0 0"/>
      <geometry>
        <sphere radius="0.001"/>
      </geometry>
      <material name="red">
        <color rgba="0.8 0.3 0.3 0.3"/>
      </material>
    </visual>
    <collision>
      <origin rpy="0 -0 0" xyz="-0.07 -0.04 0"/>
      <geometry>
        <sphere radius="0.18"/>
      </geometry>
    </collision>
  </link>
  <link name="collision_head_link_2">
    <inertial>
      <mass value="0.0001"/>
      <origin rpy="0 -0 0" xyz="0 0 0"/>
      <inertia ixx="1e-08" ixy="0" ixz="0" iyy="1e-08" iyz="0" izz="1e-08"/>
    </inertial>
    <visual>
      <origin rpy="0 -0 0" xyz="0 0 0"/>
      <geometry>
        <sphere radius="0.001"/>
      </geometry>
      <material name="red">
        <color rgba="0.8 0.3 0.3 0.3"/>
      </material>
    </visual>
    <collision>
      <origin rpy="0 -0 0" xyz="-0.07 0.04 0"/>
      <geometry>
        <sphere radius="0.18"/>
      </geometry>
    </collision>
  </link>
  <link name="display">
    <inertial>
      <mass value="0.0001"/>
      <origin rpy="0 -0 0" xyz="0 0 0"/>
      <inertia ixx="1e-08" ixy="0" ixz="0" iyy="1e-08" iyz="0" izz="1e-08"/>
    </inertial>
    <visual>
      <origin rpy="0.261799 -0 0" xyz="0 0 0"/>
      <geometry>
        <box size="0.218 0.16 0.001"/>
      </geometry>
      <material name="black">
        <color rgba="0 0 0 1"/>
      </material>
    </visual>
  </link>
  <link name="dummyhead1">
    <inertial>
      <mass value="0.0001"/>
      <origin rpy="0 -0 0" xyz="0 0 0"/>
      <inertia ixx="1e-08" ixy="0" ixz="0" iyy="1e-08" iyz="0" izz="1e-08"/>
    </inertial>
  </link>
  <link name="head">
    <inertial>
      <mass value="0.547767"/>
      <origin rpy="0 -0 0" xyz="0 0 0"/>
      <inertia ixx="0.004641" ixy="0.000159" ixz="0.000242" iyy="0.003295" iyz="-0.001324" izz="0.003415"/>
    </inertial>
    <visual>
      <origin rpy="0 -0 0" xyz="0 0 0.00953"/>
      <geometry>
        <mesh filename="package://baxter_description/meshes/head/H0.DAE" scale="1 1 1"/>
      </geometry>
      <material name="darkgray">
        <color rgba="0.2 0.2 0.2 1"/>
      </material>
    </visual>
    <collision>
      <origin rpy="0 -0 0" xyz="0 0 0"/>
      <geometry>
        <sphere radius="0.001"/>
      </geometry>
    </collision>
  </link>
  <link name="head_camera">
    <inertial>
      <mass value="0.0001"/>
      <origin rpy="0 -0 0" xyz="0 0 0"/>
      <inertia ixx="1e-08" ixy="0" ixz="0" iyy="1e-08" iyz="0" izz="1e-08"/>
    </inertial>
  </link>
  <link name="left_arm_itb">
    <inertial>
      <mass value="0.0001"/>
      <origin rpy="0 -0 0" xyz="0 0 0"/>
      <inertia ixx="1e-08" ixy="0" ixz="0" iyy="1e-08" iyz="0" izz="1e-08"/>
    </inertial>
  </link>
  <link name="left_arm_mount">
    <inertial>
      <mass value="0.0001"/>
      <origin rpy="0 -0 0" xyz="0 0 0"/>
      <inertia ixx="1e-08" ixy="0" ixz="0" iyy="1e-08" iyz="0" izz="1e-08"/>
    </inertial>
  </link>
  <!-- <link name="left_gripper"> -->
  <!--   <inertial> -->
  <!--     <mass value="0.0001"/> -->
  <!--     <origin rpy="0 -0 0" xyz="0 0 0"/> -->
  <!--     <inertia ixx="1e-08" ixy="0" ixz="0" iyy="1e-08" iyz="0" izz="1e-08"/> -->
  <!--   </inertial> -->
  <!--   <visual> -->
  <!--     <origin rpy="0 -0 0" xyz="0 0 0"/> -->
  <!--     <geometry> -->
  <!--       <box size="0.01 0.01 0.01"/> -->
  <!--     </geometry> -->
  <!--     <material name="black"> -->
  <!--       <color rgba="0 0 0 1"/> -->
  <!--     </material> -->
  <!--   </visual> -->
  <!-- </link> -->
  <!-- removed left gripper link description -->
  <link name="left_hand">
    <inertial>
      <mass value="0.19125"/>
      <origin rpy="0 -0 0" xyz="0.01093 0.00042 -0.01532"/>
      <inertia ixx="0.00017588" ixy="1.47073e-06" ixz="2.43633e-05" iyy="0.000211664" iyz="1.72689e-06" izz="0.000237454"/>
    </inertial>
    <collision>
      <origin rpy="0 -0 0" xyz="0 0 -0.0232"/>
      <geometry>
        <cylinder length="0.0464" radius="0.04"/>
      </geometry>
    </collision>
  </link>
  <link name="left_hand_accelerometer">
    <inertial>
      <mass value="0.0001"/>
      <origin rpy="0 -0 0" xyz="0 0 0"/>
      <inertia ixx="1e-08" ixy="0" ixz="0" iyy="1e-08" iyz="0" izz="1e-08"/>
    </inertial>
  </link>
  <link name="left_hand_camera">
    <inertial>
      <mass value="0.0001"/>
      <origin rpy="0 -0 0" xyz="0 0 0"/>
      <inertia ixx="1e-08" ixy="0" ixz="0" iyy="1e-08" iyz="0" izz="1e-08"/>
    </inertial>
    <visual>
      <origin rpy="0 -0 0" xyz="0 0 0"/>
      <geometry>
        <cylinder length="0.01" radius="0.02"/>
      </geometry>
      <material name="blue">
        <color rgba="0 0 1 0.8"/>
      </material>
    </visual>
  </link>
  <link name="left_hand_camera_axis">
    <inertial>
      <mass value="0.0001"/>
      <origin rpy="0 -0 0" xyz="0 0 0"/>
      <inertia ixx="1e-08" ixy="0" ixz="0" iyy="1e-08" iyz="0" izz="1e-08"/>
    </inertial>
  </link>
  <link name="left_hand_range">
    <inertial>
      <mass value="0.0001"/>
      <origin rpy="0 -0 0" xyz="0 0 0"/>
      <inertia ixx="1e-08" ixy="0" ixz="0" iyy="1e-08" iyz="0" izz="1e-08"/>
    </inertial>
    <visual>
      <origin rpy="0 -0 0" xyz="0 0 0"/>
      <geometry>
        <box size="0.005 0.02 0.005"/>
      </geometry>
      <material name="blue">
        <color rgba="0 0 1 0.8"/>
      </material>
    </visual>
  </link>
  <link name="left_lower_elbow">
    <inertial>
      <mass value="2.07206"/>
      <origin rpy="0 -0 0" xyz="0.02611 0.00159 -0.01117"/>
      <inertia ixx="0.00711583" ixy="0.000360362" ixz="0.00074595" iyy="0.0131823" iyz="-0.000196634" izz="0.00926852"/>
    </inertial>
    <visual>
      <origin rpy="0 -0 0" xyz="0 0 0"/>
      <geometry>
        <mesh filename="package://baxter_description/meshes/lower_elbow/E1.DAE" scale="1 1 1"/>
      </geometry>
      <material name="darkred">
        <color rgba="0.5 0.1 0.1 1"/>
      </material>
    </visual>
    <collision>
      <origin rpy="0 -0 0" xyz="0 0 0"/>
      <geometry>
        <cylinder length="0.18" radius="0.08"/>
      </geometry>
    </collision>
  </link>
  <link name="left_lower_forearm">
    <inertial>
      <mass value="1.60979"/>
      <origin rpy="0 -0 0" xyz="0.06041 0.00697 0.006"/>
      <inertia ixx="0.00387607" ixy="-0.000443848" ixz="-0.00021115" iyy="0.00700538" iyz="0.000153481" izz="0.00552755"/>
    </inertial>
    <visual>
      <origin rpy="0 -0 0" xyz="0 0 0"/>
      <geometry>
        <mesh filename="package://baxter_description/meshes/lower_forearm/W1.DAE" scale="1 1 1"/>
      </geometry>
      <material name="darkred">
        <color rgba="0.5 0.1 0.1 1"/>
      </material>
    </visual>
    <collision>
      <origin rpy="0 -0 0" xyz="0 0 0"/>
      <geometry>
        <cylinder length="0.16" radius="0.06"/>
      </geometry>
    </collision>
  </link>
  <link name="left_lower_shoulder">
    <inertial>
      <mass value="3.22698"/>
      <origin rpy="0 -0 0" xyz="0.06845 0.00269 -0.00529"/>
      <inertia ixx="0.0117521" ixy="-0.000300964" ixz="0.00207676" iyy="0.027886" iyz="-0.00018822" izz="0.0207875"/>
    </inertial>
    <visual>
      <origin rpy="0 -0 0" xyz="0 0 0"/>
      <geometry>
        <mesh filename="package://baxter_description/meshes/lower_shoulder/S1.DAE" scale="1 1 1"/>
      </geometry>
      <material name="darkred">
        <color rgba="0.5 0.1 0.1 1"/>
      </material>
    </visual>
    <collision>
      <origin rpy="0 -0 0" xyz="0 0 0"/>
      <geometry>
        <cylinder length="0.25" radius="0.09"/>
      </geometry>
    </collision>
  </link>
  <link name="left_torso_itb">
    <inertial>
      <mass value="0.0001"/>
      <origin rpy="0 -0 0" xyz="0 0 0"/>
      <inertia ixx="1e-08" ixy="0" ixz="0" iyy="1e-08" iyz="0" izz="1e-08"/>
    </inertial>
  </link>
  <link name="left_upper_elbow">
    <inertial>
      <mass value="4.31272"/>
      <origin rpy="0 -0 0" xyz="-0.00276 0.00132 0.18086"/>
      <inertia ixx="0.0266173" ixy="0.000292706" ixz="0.0039219" iyy="0.0284436" iyz="0.00108389" izz="0.0124801"/>
    </inertial>
    <visual>
      <origin rpy="0 -0 0" xyz="0 0 0"/>
      <geometry>
        <mesh filename="package://baxter_description/meshes/upper_elbow/E0.DAE" scale="1 1 1"/>
      </geometry>
      <material name="darkred">
        <color rgba="0.5 0.1 0.1 1"/>
      </material>
    </visual>
    <collision>
      <origin rpy="0 -0 0" xyz="0 0 -0.0535"/>
      <geometry>
        <cylinder length="0.107" radius="0.09"/>
      </geometry>
    </collision>
  </link>
  <link name="left_upper_elbow_visual">
    <inertial>
      <mass value="0.0001"/>
      <origin rpy="0 -0 0" xyz="0 0 0"/>
      <inertia ixx="1e-08" ixy="0" ixz="0" iyy="1e-08" iyz="0" izz="1e-08"/>
    </inertial>
    <collision>
      <origin rpy="0 -0 0" xyz="0 0 0.1365"/>
      <geometry>
        <cylinder length="0.3" radius="0.09"/>
      </geometry>
    </collision>
  </link>
  <link name="left_upper_forearm">
    <inertial>
      <mass value="2.24665"/>
      <origin rpy="0 -0 0" xyz="-0.00168 0.0046 0.13952"/>
      <inertia ixx="0.0166774" ixy="0.000184037" ixz="0.000186576" iyy="0.0167546" iyz="-0.000647324" izz="0.00374631"/>
    </inertial>
    <visual>
      <origin rpy="0 -0 0" xyz="0 0 0"/>
      <geometry>
        <mesh filename="package://baxter_description/meshes/upper_forearm/W0.DAE" scale="1 1 1"/>
      </geometry>
      <material name="darkred">
        <color rgba="0.5 0.1 0.1 1"/>
      </material>
    </visual>
    <collision>
      <origin rpy="0 -0 0" xyz="0 0 -0.044"/>
      <geometry>
        <cylinder length="0.088" radius="0.07"/>
      </geometry>
    </collision>
  </link>
  <link name="left_upper_forearm_visual">
    <inertial>
      <mass value="0.0001"/>
      <origin rpy="0 -0 0" xyz="0 0 0"/>
      <inertia ixx="1e-08" ixy="0" ixz="0" iyy="1e-08" iyz="0" izz="1e-08"/>
    </inertial>
    <collision>
      <origin rpy="0 -0 0" xyz="0 0 0.136"/>
      <geometry>
        <cylinder length="0.272" radius="0.07"/>
      </geometry>
    </collision>
  </link>
  <link name="left_upper_shoulder">
    <inertial>
      <mass value="5.70044"/>
      <origin rpy="0 -0 0" xyz="0.01783 0.00086 0.19127"/>
      <inertia ixx="0.047091" ixy="0.000127876" ixz="0.0061487" iyy="0.0376698" iyz="0.000780869" izz="0.0359599"/>
    </inertial>
    <visual>
      <origin rpy="0 -0 0" xyz="0 0 0"/>
      <geometry>
        <mesh filename="package://baxter_description/meshes/upper_shoulder/S0.DAE" scale="1 1 1"/>
      </geometry>
      <material name="darkred">
        <color rgba="0.5 0.1 0.1 1"/>
      </material>
    </visual>
    <collision>
      <origin rpy="0 -0 0" xyz="0 0 0.1361"/>
      <geometry>
        <cylinder length="0.35" radius="0.1"/>
      </geometry>
    </collision>
  </link>
  <link name="left_wrist">
    <inertial>
      <mass value="0.35093"/>
      <origin rpy="0 -0 0" xyz="0.00198 0.00125 0.01855"/>
      <inertia ixx="0.000252892" ixy="5.75311e-06" ixz="-1.59345e-06" iyy="0.00026886" iyz="-5.19818e-06" izz="0.000307412"/>
    </inertial>
    <visual>
      <origin rpy="0 -0 0" xyz="0 0 0"/>
      <geometry>
        <mesh filename="package://baxter_description/meshes/wrist/W2.DAE" scale="1 1 1"/>
      </geometry>
      <material name="lightgrey">
        <color rgba="0.1 0.1 0.1 1"/>
      </material>
    </visual>
    <collision>
      <origin rpy="0 -0 0" xyz="0 0 0"/>
      <geometry>
        <cylinder length="0.165" radius="0.06"/>
      </geometry>
    </collision>
  </link>
  <link name="pedestal">
    <inertial>
      <mass value="60.864"/>
      <origin rpy="0 -0 0" xyz="0 0 0"/>
      <inertia ixx="5.06359" ixy="0.00103417" ixz="0.801996" iyy="6.08689" iyz="0.00105311" izz="4.96192"/>
    </inertial>
    <visual>
      <origin rpy="0 -0 0" xyz="0 0 0"/>
      <geometry>
        <mesh filename="package://baxter_description/meshes/base/PEDESTAL.DAE" scale="1 1 1"/>
      </geometry>
      <material name="darkgray">
        <color rgba="0.2 0.2 0.2 1"/>
      </material>
    </visual>
    <collision>
      <origin rpy="0 0 0" xyz="0 0 -0.36"/>
      <geometry>
        <cylinder length="0.6" radius="0.15"/>
      </geometry>
    </collision>
    <collision>
      <origin rpy="0 0 0" xyz="0 0 -0.12"/>
      <geometry>
        <cylinder length="0.11" radius="0.19"/>
      </geometry>
    </collision>
    <!-- center of base -->
    <collision>
      <origin rpy="0 0 0" xyz="-0.05 0 -0.78"/>
      <geometry>
        <box size="0.6 0.375 0.28"/>
      </geometry>
    </collision>
    <!-- forward wheels -->
    <collision>
      <origin rpy="0 0 0" xyz="0.325 0.25 -0.78"/>
      <geometry>
        <box size="0.2 0.325 0.28"/>
      </geometry>
    </collision>
    <collision>
      <origin rpy="0 0 0" xyz="0.325 -0.25 -0.78"/>
      <geometry>
        <box size="0.2 0.325 0.28"/>
      </geometry>
    </collision>
    <!-- rear wheels -->
    <collision>
      <origin rpy="0 0 0" xyz="-0.425 0.25 -0.78"/>
      <geometry>
        <box size="0.2 0.325 0.28"/>
      </geometry>
    </collision>
    <collision>
      <origin rpy="0 0 0" xyz="-0.425 -0.25 -0.78"/>
      <geometry>
        <box size="0.2 0.325 0.28"/>
      </geometry>
    </collision>
  </link>
  <link name="right_arm_itb">
    <inertial>
      <mass value="0.0001"/>
      <origin rpy="0 -0 0" xyz="0 0 0"/>
      <inertia ixx="1e-08" ixy="0" ixz="0" iyy="1e-08" iyz="0" izz="1e-08"/>
    </inertial>
  </link>
  <link name="right_arm_mount">
    <inertial>
      <mass value="0.0001"/>
      <origin rpy="0 -0 0" xyz="0 0 0"/>
      <inertia ixx="1e-08" ixy="0" ixz="0" iyy="1e-08" iyz="0" izz="1e-08"/>
    </inertial>
  </link>
  <!-- <link name="right_gripper"> -->
  <!--   <inertial> -->
  <!--     <mass value="0.0001"/> -->
  <!--     <origin rpy="0 -0 0" xyz="0 0 0"/> -->
  <!--     <inertia ixx="1e-08" ixy="0" ixz="0" iyy="1e-08" iyz="0" izz="1e-08"/> -->
  <!--   </inertial> -->
  <!--   <visual> -->
  <!--     <origin rpy="0 -0 0" xyz="0 0 0"/> -->
  <!--     <geometry> -->
  <!--       <box size="0.01 0.01 0.01"/> -->
  <!--     </geometry> -->
  <!--     <material name="black"> -->
  <!--       <color rgba="0 0 0 1"/> -->
  <!--     </material> -->
  <!--   </visual> -->
  <!-- </link> -->
  <!-- removed right gripper description -->
  <link name="right_hand">
    <inertial>
      <mass value="0.19125"/>
      <origin rpy="0 -0 0" xyz="0.01093 0.00042 -0.01532"/>
      <inertia ixx="0.00017588" ixy="1.47073e-06" ixz="2.43633e-05" iyy="0.000211664" iyz="1.72689e-06" izz="0.000237454"/>
    </inertial>
    <collision>
      <origin rpy="0 -0 0" xyz="0 0 -0.0232"/>
      <geometry>
        <cylinder length="0.0464" radius="0.04"/>
      </geometry>
    </collision>
  </link>
  <link name="right_hand_accelerometer">
    <inertial>
      <mass value="0.0001"/>
      <origin rpy="0 -0 0" xyz="0 0 0"/>
      <inertia ixx="1e-08" ixy="0" ixz="0" iyy="1e-08" iyz="0" izz="1e-08"/>
    </inertial>
  </link>
  <link name="right_hand_camera">
    <inertial>
      <mass value="0.0001"/>
      <origin rpy="0 -0 0" xyz="0 0 0"/>
      <inertia ixx="1e-08" ixy="0" ixz="0" iyy="1e-08" iyz="0" izz="1e-08"/>
    </inertial>
    <visual>
      <origin rpy="0 -0 0" xyz="0 0 0"/>
      <geometry>
        <cylinder length="0.01" radius="0.02"/>
      </geometry>
      <material name="blue">
        <color rgba="0 0 1 0.8"/>
      </material>
    </visual>
  </link>
  <link name="right_hand_camera_axis">
    <inertial>
      <mass value="0.0001"/>
      <origin rpy="0 -0 0" xyz="0 0 0"/>
      <inertia ixx="1e-08" ixy="0" ixz="0" iyy="1e-08" iyz="0" izz="1e-08"/>
    </inertial>
  </link>
  <link name="right_hand_range">
    <inertial>
      <mass value="0.0001"/>
      <origin rpy="0 -0 0" xyz="0 0 0"/>
      <inertia ixx="1e-08" ixy="0" ixz="0" iyy="1e-08" iyz="0" izz="1e-08"/>
    </inertial>
    <visual>
      <origin rpy="0 -0 0" xyz="0 0 0"/>
      <geometry>
        <box size="0.005 0.02 0.005"/>
      </geometry>
      <material name="blue">
        <color rgba="0 0 1 0.8"/>
      </material>
    </visual>
  </link>
  <link name="right_lower_elbow">
    <inertial>
      <mass value="2.07206"/>
      <origin rpy="0 -0 0" xyz="0.02611 0.00159 -0.01117"/>
      <inertia ixx="0.00711583" ixy="0.000360362" ixz="0.00074595" iyy="0.0131823" iyz="-0.000196634" izz="0.00926852"/>
    </inertial>
    <visual>
      <origin rpy="0 -0 0" xyz="0 0 0"/>
      <geometry>
        <mesh filename="package://baxter_description/meshes/lower_elbow/E1.DAE" scale="1 1 1"/>
      </geometry>
      <material name="darkred">
        <color rgba="0.5 0.1 0.1 1"/>
      </material>
    </visual>
    <collision>
      <origin rpy="0 -0 0" xyz="0 0 0"/>
      <geometry>
        <cylinder length="0.18" radius="0.08"/>
      </geometry>
    </collision>
  </link>
  <link name="right_lower_forearm">
    <inertial>
      <mass value="1.60979"/>
      <origin rpy="0 -0 0" xyz="0.06041 0.00697 0.006"/>
      <inertia ixx="0.00387607" ixy="-0.000443848" ixz="-0.00021115" iyy="0.00700538" iyz="0.000153481" izz="0.00552755"/>
    </inertial>
    <visual>
      <origin rpy="0 -0 0" xyz="0 0 0"/>
      <geometry>
        <mesh filename="package://baxter_description/meshes/lower_forearm/W1.DAE" scale="1 1 1"/>
      </geometry>
      <material name="darkred">
        <color rgba="0.5 0.1 0.1 1"/>
      </material>
    </visual>
    <collision>
      <origin rpy="0 -0 0" xyz="0 0 0"/>
      <geometry>
        <cylinder length="0.16" radius="0.06"/>
      </geometry>
    </collision>
  </link>
  <link name="right_lower_shoulder">
    <inertial>
      <mass value="3.22698"/>
      <origin rpy="0 -0 0" xyz="0.06845 0.00269 -0.00529"/>
      <inertia ixx="0.0117521" ixy="-0.000300964" ixz="0.00207676" iyy="0.027886" iyz="-0.00018822" izz="0.0207875"/>
    </inertial>
    <visual>
      <origin rpy="0 -0 0" xyz="0 0 0"/>
      <geometry>
        <mesh filename="package://baxter_description/meshes/lower_shoulder/S1.DAE" scale="1 1 1"/>
      </geometry>
      <material name="darkred">
        <color rgba="0.5 0.1 0.1 1"/>
      </material>
    </visual>
    <collision>
      <origin rpy="0 -0 0" xyz="0 0 0"/>
      <geometry>
        <cylinder length="0.25" radius="0.09"/>
      </geometry>
    </collision>
  </link>
  <link name="right_torso_itb">
    <inertial>
      <mass value="0.0001"/>
      <origin rpy="0 -0 0" xyz="0 0 0"/>
      <inertia ixx="1e-08" ixy="0" ixz="0" iyy="1e-08" iyz="0" izz="1e-08"/>
    </inertial>
  </link>
  <link name="right_upper_elbow">
    <inertial>
      <mass value="4.31272"/>
      <origin rpy="0 -0 0" xyz="-0.00276 0.00132 0.18086"/>
      <inertia ixx="0.0266173" ixy="0.000292706" ixz="0.0039219" iyy="0.0284436" iyz="0.00108389" izz="0.0124801"/>
    </inertial>
    <visual>
      <origin rpy="0 -0 0" xyz="0 0 0"/>
      <geometry>
        <mesh filename="package://baxter_description/meshes/upper_elbow/E0.DAE" scale="1 1 1"/>
      </geometry>
      <material name="darkred">
        <color rgba="0.5 0.1 0.1 1"/>
      </material>
    </visual>
    <collision>
      <origin rpy="0 -0 0" xyz="0 0 -0.0535"/>
      <geometry>
        <cylinder length="0.107" radius="0.09"/>
      </geometry>
    </collision>
  </link>
  <link name="right_upper_elbow_visual">
    <inertial>
      <mass value="0.0001"/>
      <origin rpy="0 -0 0" xyz="0 0 0"/>
      <inertia ixx="1e-08" ixy="0" ixz="0" iyy="1e-08" iyz="0" izz="1e-08"/>
    </inertial>
    <collision>
      <origin rpy="0 -0 0" xyz="0 0 0.1365"/>
      <geometry>
        <cylinder length="0.3" radius="0.09"/>
      </geometry>
    </collision>
  </link>
  <link name="right_upper_forearm">
    <inertial>
      <mass value="2.24665"/>
      <origin rpy="0 -0 0" xyz="-0.00168 0.0046 0.13952"/>
      <inertia ixx="0.0166774" ixy="0.000184037" ixz="0.000186576" iyy="0.0167546" iyz="-0.000647324" izz="0.00374631"/>
    </inertial>
    <visual>
      <origin rpy="0 -0 0" xyz="0 0 0"/>
      <geometry>
        <mesh filename="package://baxter_description/meshes/upper_forearm/W0.DAE" scale="1 1 1"/>
      </geometry>
      <material name="darkred">
        <color rgba="0.5 0.1 0.1 1"/>
      </material>
    </visual>
    <collision>
      <origin rpy="0 -0 0" xyz="0 0 -0.044"/>
      <geometry>
        <cylinder length="0.088" radius="0.07"/>
      </geometry>
    </collision>
  </link>
  <link name="right_upper_forearm_visual">
    <inertial>
      <mass value="0.0001"/>
      <origin rpy="0 -0 0" xyz="0 0 0"/>
      <inertia ixx="1e-08" ixy="0" ixz="0" iyy="1e-08" iyz="0" izz="1e-08"/>
    </inertial>
    <collision>
      <origin rpy="0 -0 0" xyz="0 0 0.136"/>
      <geometry>
        <cylinder length="0.272" radius="0.07"/>
      </geometry>
    </collision>
  </link>
  <link name="right_upper_shoulder">
    <inertial>
      <mass value="5.70044"/>
      <origin rpy="0 -0 0" xyz="0.01783 0.00086 0.19127"/>
      <inertia ixx="0.047091" ixy="0.000127876" ixz="0.0061487" iyy="0.0376698" iyz="0.000780869" izz="0.0359599"/>
    </inertial>
    <visual>
      <origin rpy="0 -0 0" xyz="0 0 0"/>
      <geometry>
        <mesh filename="package://baxter_description/meshes/upper_shoulder/S0.DAE" scale="1 1 1"/>
      </geometry>
      <material name="darkred">
        <color rgba="0.5 0.1 0.1 1"/>
      </material>
    </visual>
    <collision>
      <origin rpy="0 -0 0" xyz="0 0 0.1361"/>
      <geometry>
        <cylinder length="0.35" radius="0.1"/>
      </geometry>
    </collision>
  </link>
  <link name="right_wrist">
    <inertial>
      <mass value="0.35093"/>
      <origin rpy="0 -0 0" xyz="0.00198 0.00125 0.01855"/>
      <inertia ixx="0.000252892" ixy="5.75311e-06" ixz="-1.59345e-06" iyy="0.00026886" iyz="-5.19818e-06" izz="0.000307412"/>
    </inertial>
    <visual>
      <origin rpy="0 -0 0" xyz="0 0 0"/>
      <geometry>
        <mesh filename="package://baxter_description/meshes/wrist/W2.DAE" scale="1 1 1"/>
      </geometry>
      <material name="lightgrey">
        <color rgba="0.1 0.1 0.1 1"/>
      </material>
    </visual>
    <collision>
      <origin rpy="0 -0 0" xyz="0 0 0"/>
      <geometry>
        <cylinder length="0.165" radius="0.06"/>
      </geometry>
    </collision>
  </link>
  <link name="screen">
    <inertial>
      <mass value="0.440171"/>
      <origin rpy="0 -0 0" xyz="0 0 0"/>
      <inertia ixx="0.004006" ixy="0.00023" ixz="2e-06" iyy="0.0028" iyz="2.9e-05" izz="0.001509"/>
    </inertial>
    <visual>
      <origin rpy="3.14159 -1.57079 3.14159" xyz="0 -0.00953 -0.0347"/>
      <geometry>
        <mesh filename="package://baxter_description/meshes/head/H1.DAE" scale="1 1 1"/>
      </geometry>
      <material name="darkred">
        <color rgba="0.5 0.1 0.1 1"/>
      </material>
    </visual>
    <collision>
      <origin rpy="0 -0 0" xyz="0 0 0"/>
      <geometry>
        <sphere radius="0.001"/>
      </geometry>
    </collision>
  </link>
  <link name="sonar_ring">
    <inertial>
      <mass value="0.0001"/>
      <origin rpy="0 -0 0" xyz="0 0 0"/>
      <inertia ixx="1e-08" ixy="0" ixz="0" iyy="1e-08" iyz="0" izz="1e-08"/>
    </inertial>
    <visual>
      <origin rpy="0 -0 0" xyz="-0.0347 0 0.00953"/>
      <geometry>
        <cylinder length="0.01" radius="0.085"/>
      </geometry>
      <material name="darkgray">
        <color rgba="0.2 0.2 0.2 1"/>
      </material>
    </visual>
    <collision>
      <origin rpy="0 -0 0" xyz="0 0 0"/>
      <geometry>
        <sphere radius="0.001"/>
      </geometry>
    </collision>
  </link>
  <link name="torso">
    <inertial>
      <mass value="35.3365"/>
      <origin rpy="0 -0 0" xyz="0 0 0"/>
      <inertia ixx="1.84916" ixy="-0.000354" ixz="-0.154188" iyy="1.66267" iyz="0.003292" izz="0.802239"/>
    </inertial>
    <visual>
      <origin rpy="0 -0 0" xyz="0 0 0"/>
      <geometry>
        <mesh filename="package://baxter_description/meshes/torso/base_link.DAE" scale="1 1 1"/>
      </geometry>
      <material name="darkgray">
        <color rgba="0.2 0.2 0.2 1"/>
      </material>
    </visual>
    <collision>
      <origin rpy="0 0 0" xyz="0 0 0"/>
      <geometry>
        <mesh filename="package://baxter_description/meshes/torso/base_link.DAE"/>
      </geometry>
    </collision>
  </link>
  <joint name="collision_head_1" type="fixed">
    <origin rpy="0 -0 0" xyz="0.11 0 0.75"/>
    <axis xyz="0 0 0"/>
    <parent link="base"/>
    <child link="collision_head_link_1"/>
  </joint>
  <joint name="collision_head_2" type="fixed">
    <origin rpy="0 -0 0" xyz="0.11 0 0.75"/>
    <axis xyz="0 0 0"/>
    <parent link="base"/>
    <child link="collision_head_link_2"/>
  </joint>
  <joint name="display_joint" type="fixed">
    <origin rpy="0 -0 0" xyz="0 -0.016 0"/>
    <axis xyz="0 0 0"/>
    <parent link="screen"/>
    <child link="display"/>
  </joint>
  <joint name="dummy" type="fixed">
    <origin rpy="0 -0 0" xyz="0 0 0"/>
    <axis xyz="0 0 0"/>
    <parent link="head"/>
    <child link="dummyhead1"/>
  </joint>
  <joint name="head_camera" type="fixed">
    <origin rpy="1.75057 3.87602e-18 1.5708" xyz="0.12839 0 0.06368"/>
    <axis xyz="0 0 0"/>
    <parent link="head"/>
    <child link="head_camera"/>
  </joint>
  <joint name="head_nod" type="fixed">
    <origin rpy="1.75057 3.87602e-18 1.5708" xyz="0.1227 0 0"/>
    <axis xyz="0 0 0"/>
    <parent link="head"/>
    <child link="screen"/>
  </joint>
  <joint name="head_pan" type="revolute">
    <origin rpy="0 -0 0" xyz="0.06 0 0.686"/>
    <axis xyz="0 0 1"/>
    <parent link="torso"/>
    <child link="head"/>
    <dynamics damping="0.7" friction="0"/>
    <limit effort="50000" lower="-1.5708" upper="1.5708" velocity="10000"/>
  </joint>
  <joint name="left_e0" type="revolute">
    <origin rpy="1.5708 -1.14194e-16 1.5708" xyz="0.102 0 0"/>
    <axis xyz="0 0 1"/>
    <parent link="left_lower_shoulder"/>
    <child link="left_upper_elbow"/>
    <dynamics damping="0.7" friction="0"/>
    <limit effort="50" lower="-3.05418" upper="3.05418" velocity="1.5"/>
  </joint>
  <joint name="left_e0_fixed" type="fixed">
    <origin rpy="1.5708 -1.14194e-16 1.5708" xyz="0.107 0 0"/>
    <axis xyz="0 0 0"/>
    <parent link="left_lower_shoulder"/>
    <child link="left_upper_elbow_visual"/>
  </joint>
  <joint name="left_e1" type="revolute">
    <origin rpy="1.57078 -1.57079 -3.14158" xyz="0.069 0 0.26242"/>
    <axis xyz="0 0 1"/>
    <parent link="left_upper_elbow"/>
    <child link="left_lower_elbow"/>
    <dynamics damping="0.7" friction="0"/>
    <limit effort="50" lower="-0.05" upper="2.618" velocity="1.5"/>
  </joint>
  <!-- removed left joint description -->
  <!-- <joint name="left_gripper_base" type="fixed"> -->
  <!--   <origin rpy="0 -0 0" xyz="0 0 0"/> -->
  <!--   <axis xyz="0 0 0"/> -->
  <!--   <parent link="left_hand"/> -->
  <!--   <child link="left_gripper_base"/> -->
  <!-- </joint> -->
  <joint name="left_hand" type="fixed">
    <origin rpy="0 -0 0" xyz="0 0 0.11355"/>
    <axis xyz="0 0 0"/>
    <parent link="left_wrist"/>
    <child link="left_hand"/>
  </joint>
  <joint name="left_hand_accelerometer" type="fixed">
    <origin rpy="0 -0 0" xyz="0.00198 0.000133 -0.0146"/>
    <axis xyz="0 0 0"/>
    <parent link="left_hand"/>
    <child link="left_hand_accelerometer"/>
  </joint>
  <joint name="left_hand_camera" type="fixed">
    <origin rpy="0 0 -1.5708" xyz="0.03825 0.012 0.015355"/>
    <axis xyz="0 0 0"/>
    <parent link="left_hand"/>
    <child link="left_hand_camera"/>
  </joint>
  <joint name="left_hand_camera_axis" type="fixed">
    <origin rpy="0 -0 0" xyz="0.03825 0.012 0"/>
    <axis xyz="0 0 0"/>
    <parent link="left_hand"/>
    <child link="left_hand_camera_axis"/>
  </joint>
  <joint name="left_hand_range" type="fixed">
    <origin rpy="-3.14158 -1.57079 1.57078" xyz="0.032 -0.020245 0.0288"/>
    <axis xyz="0 0 0"/>
    <parent link="left_hand"/>
    <child link="left_hand_range"/>
  </joint>
  <joint name="left_s0" type="revolute">
    <origin rpy="0 -0 0" xyz="0.055695 0 0.011038"/>
    <axis xyz="0 0 1"/>
    <parent link="left_arm_mount"/>
    <child link="left_upper_shoulder"/>
    <dynamics damping="0.7" friction="0"/>
    <limit effort="50" lower="-1.70168" upper="1.70168" velocity="1.5"/>
  </joint>
  <joint name="left_s1" type="revolute">
    <origin rpy="-1.5708 0 0" xyz="0.069 0 0.27035"/>
    <axis xyz="0 0 1"/>
    <parent link="left_upper_shoulder"/>
    <child link="left_lower_shoulder"/>
    <dynamics damping="0.7" friction="0"/>
    <limit effort="50" lower="-2.147" upper="1.047" velocity="1.5"/>
  </joint>
  <joint name="left_torso_arm_mount" type="fixed">
    <origin rpy="-0.00479639 0.00185872 0.779972" xyz="0.0252503 0.219489 0.109759"/>
    <axis xyz="0 0 0"/>
    <parent link="torso"/>
    <child link="left_arm_mount"/>
  </joint>
  <joint name="left_torso_itb_fixed" type="fixed">
    <origin rpy="1.5708 9.26536e-05 -3.14159" xyz="-0.08897 0.15593 0.389125"/>
    <axis xyz="0 0 0"/>
    <parent link="torso"/>
    <child link="left_torso_itb"/>
  </joint>
  <joint name="left_w0" type="revolute">
    <origin rpy="1.5708 -1.14194e-16 1.5708" xyz="0.10359 0 0"/>
    <axis xyz="0 0 1"/>
    <parent link="left_lower_elbow"/>
    <child link="left_upper_forearm"/>
    <dynamics damping="0.7" friction="0"/>
    <limit effort="15" lower="-3.059" upper="3.059" velocity="4"/>
  </joint>
  <joint name="left_w0_fixed" type="fixed">
    <origin rpy="1.5708 -1.14194e-16 1.5708" xyz="0.088 0 0"/>
    <axis xyz="0 0 0"/>
    <parent link="left_lower_elbow"/>
    <child link="left_upper_forearm_visual"/>
  </joint>
  <joint name="left_w0_to_itb_fixed" type="fixed">
    <origin rpy="-1.5708 1.14194e-16 1.5708" xyz="-0.0565 0 0.12"/>
    <axis xyz="0 0 0"/>
    <parent link="left_upper_forearm"/>
    <child link="left_arm_itb"/>
  </joint>
  <joint name="left_w1" type="revolute">
    <origin rpy="1.57078 -1.57079 -3.14158" xyz="0.01 0 0.2707"/>
    <axis xyz="0 0 1"/>
    <parent link="left_upper_forearm"/>
    <child link="left_lower_forearm"/>
    <dynamics damping="0.7" friction="0"/>
    <limit effort="15" lower="-1.5708" upper="2.094" velocity="4"/>
  </joint>
  <joint name="left_w2" type="revolute">
    <origin rpy="1.5708 -1.14194e-16 1.5708" xyz="0.115975 0 0"/>
    <axis xyz="0 0 1"/>
    <parent link="left_lower_forearm"/>
    <child link="left_wrist"/>
    <dynamics damping="0.7" friction="0"/>
    <limit effort="15" lower="-3.059" upper="3.059" velocity="4"/>
  </joint>
  <joint name="pedestal_fixed" type="fixed">
    <origin rpy="0 -0 0" xyz="0 0 0"/>
    <axis xyz="0 0 0"/>
    <parent link="torso"/>
    <child link="pedestal"/>
  </joint>
  <joint name="right_e0" type="revolute">
    <origin rpy="1.5708 -1.14194e-16 1.5708" xyz="0.102 0 0"/>
    <axis xyz="0 0 1"/>
    <parent link="right_lower_shoulder"/>
    <child link="right_upper_elbow"/>
    <dynamics damping="0.7" friction="0"/>
    <limit effort="50" lower="-3.05418" upper="3.05418" velocity="1.5"/>
  </joint>
  <joint name="right_e0_fixed" type="fixed">
    <origin rpy="1.5708 -1.14194e-16 1.5708" xyz="0.107 0 0"/>
    <axis xyz="0 0 0"/>
    <parent link="right_lower_shoulder"/>
    <child link="right_upper_elbow_visual"/>
  </joint>
  <joint name="right_e1" type="revolute">
    <origin rpy="1.57078 -1.57079 -3.14158" xyz="0.069 0 0.26242"/>
    <axis xyz="0 0 1"/>
    <parent link="right_upper_elbow"/>
    <child link="right_lower_elbow"/>
    <dynamics damping="0.7" friction="0"/>
    <limit effort="50" lower="-0.05" upper="2.618" velocity="1.5"/>
  </joint>
  <!-- removed right joint description -->
  <!-- <joint name="right_gripper_base" type="fixed"> -->
  <!--   <origin rpy="0 -0 0" xyz="0 0 0"/> -->
  <!--   <axis xyz="0 0 0"/> -->
  <!--   <parent link="right_hand"/> -->
  <!--   <child link="right_gripper_base"/> -->
  <!-- </joint> -->
  <joint name="right_hand" type="fixed">
    <origin rpy="0 -0 0" xyz="0 0 0.11355"/>
    <axis xyz="0 0 0"/>
    <parent link="right_wrist"/>
    <child link="right_hand"/>
  </joint>
  <joint name="right_hand_accelerometer" type="fixed">
    <origin rpy="0 -0 0" xyz="0.00198 0.000133 -0.0146"/>
    <axis xyz="0 0 0"/>
    <parent link="right_hand"/>
    <child link="right_hand_accelerometer"/>
  </joint>
  <joint name="right_hand_camera" type="fixed">
    <origin rpy="0 0 -1.5708" xyz="0.03825 0.012 0.015355"/>
    <axis xyz="0 0 0"/>
    <parent link="right_hand"/>
    <child link="right_hand_camera"/>
  </joint>
  <joint name="right_hand_camera_axis" type="fixed">
    <origin rpy="0 -0 0" xyz="0.03825 0.012 0"/>
    <axis xyz="0 0 0"/>
    <parent link="right_hand"/>
    <child link="right_hand_camera_axis"/>
  </joint>
  <joint name="right_hand_range" type="fixed">
    <origin rpy="-3.14158 -1.57079 1.57078" xyz="0.032 -0.020245 0.0288"/>
    <axis xyz="0 0 0"/>
    <parent link="right_hand"/>
    <child link="right_hand_range"/>
  </joint>
  <joint name="right_s0" type="revolute">
    <origin rpy="0 -0 0" xyz="0.055695 0 0.011038"/>
    <axis xyz="0 0 1"/>
    <parent link="right_arm_mount"/>
    <child link="right_upper_shoulder"/>
    <dynamics damping="0.7" friction="0"/>
    <limit effort="50" lower="-1.70168" upper="1.70168" velocity="1.5"/>
  </joint>
  <joint name="right_s1" type="revolute">
    <origin rpy="-1.5708 0 0" xyz="0.069 0 0.27035"/>
    <axis xyz="0 0 1"/>
    <parent link="right_upper_shoulder"/>
    <child link="right_lower_shoulder"/>
    <dynamics damping="0.7" friction="0"/>
    <limit effort="50" lower="-2.147" upper="1.047" velocity="1.5"/>
  </joint>
  <joint name="right_torso_arm_mount" type="fixed">
    <origin rpy="0.0174986 0.00342261 -0.785584" xyz="0.023277 -0.21986 0.10804"/>
    <axis xyz="0 0 0"/>
    <parent link="torso"/>
    <child link="right_arm_mount"/>
  </joint>
  <joint name="right_torso_itb_fixed" type="fixed">
    <origin rpy="1.5708 -0 0" xyz="-0.08897 -0.15593 0.389125"/>
    <axis xyz="0 0 0"/>
    <parent link="torso"/>
    <child link="right_torso_itb"/>
  </joint>
  <joint name="right_w0" type="revolute">
    <origin rpy="1.5708 -1.14194e-16 1.5708" xyz="0.10359 0 0"/>
    <axis xyz="0 0 1"/>
    <parent link="right_lower_elbow"/>
    <child link="right_upper_forearm"/>
    <dynamics damping="0.7" friction="0"/>
    <limit effort="15" lower="-3.059" upper="3.059" velocity="4"/>
  </joint>
  <joint name="right_w0_fixed" type="fixed">
    <origin rpy="1.5708 -1.14194e-16 1.5708" xyz="0.088 0 0"/>
    <axis xyz="0 0 0"/>
    <parent link="right_lower_elbow"/>
    <child link="right_upper_forearm_visual"/>
  </joint>
  <joint name="right_w0_to_itb_fixed" type="fixed">
    <origin rpy="-1.5708 1.14194e-16 1.5708" xyz="-0.0565 0 0.12"/>
    <axis xyz="0 0 0"/>
    <parent link="right_upper_forearm"/>
    <child link="right_arm_itb"/>
  </joint>
  <joint name="right_w1" type="revolute">
    <origin rpy="1.57078 -1.57079 -3.14158" xyz="0.01 0 0.2707"/>
    <axis xyz="0 0 1"/>
    <parent link="right_upper_forearm"/>
    <child link="right_lower_forearm"/>
    <dynamics damping="0.7" friction="0"/>
    <limit effort="15" lower="-1.5708" upper="2.094" velocity="4"/>
  </joint>
  <joint name="right_w2" type="revolute">
    <origin rpy="1.5708 -1.14194e-16 1.5708" xyz="0.115975 0 0"/>
    <axis xyz="0 0 1"/>
    <parent link="right_lower_forearm"/>
    <child link="right_wrist"/>
    <dynamics damping="0.7" friction="0"/>
    <limit effort="15" lower="-3.059" upper="3.059" velocity="4"/>
  </joint>
  <joint name="sonar_s0" type="fixed">
    <origin rpy="0 -0 0" xyz="0.0947 0 0.817"/>
    <axis xyz="0 0 0"/>
    <parent link="torso"/>
    <child link="sonar_ring"/>
  </joint>
  <joint name="torso_t0" type="fixed">
    <origin rpy="0 -0 0" xyz="0 0 0"/>
    <axis xyz="0 0 0"/>
    <parent link="base"/>
    <child link="torso"/>
    <limit effort="50000" lower="-3.01" upper="3.01" velocity="10000"/>
  </joint>
  <material name="black">
    <color rgba="0 0 0 1"/>
  </material>
  <material name="blue">
    <color rgba="0 0 1 0.8"/>
  </material>
  <material name="darkgray">
    <color rgba="0.2 0.2 0.2 1"/>
  </material>
  <material name="darkred">
    <color rgba="0.5 0.1 0.1 1"/>
  </material>
  <material name="lightgrey">
    <color rgba="0.1 0.1 0.1 1"/>
  </material>
  <material name="red">
    <color rgba="0.8 0.3 0.3 0.3"/>
  </material>
  <!-- <xacro:include filename="$(find ros_finger_sensor)/urdf/electric_gripper.urdf.xacro" /> -->
  <!-- open hand urdf files -->
  <!-- <xacro:include filename="$(find ros_finger_sensor)/urdf/model_t.urdf.xacro" /> -->
  <!-- <xacro:include filename="$(find ros_finger_sesnsor)/urdf/model_o.urdf.xacro" /> -->
  <!-- UNCOMMENT THE GRIPPERS THAT CORRESPOND TO YOUR CONFIGURATION -->
  <!-- *** BAXTER ELECTRIC PARALLEL GRIPPER *** -->
  <!-- <xacro:electric_parallel_gripper arm="left" /> -->
  <!-- <xacro:electric_parallel_gripper arm="right" /> -->
  <!-- *** YALE OPEN HAND GRIPPERS *** -->
  <!-- MODEL T -->
  <!-- xacro:model_t arm="left"/ -->
  <!-- <xacro:model_t arm="right"/> -->
  <!-- MODEL O -->
  <!-- xacro:model_o arm="left"/ -->
  <!-- xacro:model_o arm="right"/ -->
</robot>

