<?xml version="1.0" ?>
<robot name="baxter"
       xmlns:xacro="http://www.ros.org/wiki/xacro"
       xmlns:xi="http://www.w3.org/2001/XInclude">

<xacro:macro name="electric_parallel_gripper" params="arm">

  <!-- Left finger -->
  <link name="${arm}_gripper_l_finger">
    <visual>
      <origin rpy="0 -1.57079632679 0" xyz="0.0 -0.036 -0.0135"/>
      <geometry>
        <mesh filename="package://baxter_description/meshes/electric_gripper/fingers/extended_narrow.DAE" /> <!-- Long left finger-->
      </geometry>
      <material name="black">
        <color rgba="0 0 0 1" />
      </material>
    </visual>
    <collision>
      <origin rpy="1.57 0 0" xyz="0.00 0.02 0.005" />
      <geometry>
	<cylinder length="0.115" radius="0.008" />
      </geometry>
    </collision>
    <inertial>
      <origin rpy="0 0 0" xyz="0.000000 0.000000 0.000000"/>
      <mass value="0.00094542"/>
      <inertia ixx="2e-08" ixy="0" ixz="0" iyy="3e-08" iyz="0" izz="2e-08"/>
    </inertial>
  </link>

  <!-- Right finger -->
  <link name="${arm}_gripper_r_finger">
    <visual>
      <origin rpy="0 1.57079632679 0" xyz="0.0 -0.036 0.0135"/>
      <geometry>
        <mesh filename="package://baxter_description/meshes/electric_gripper/fingers/extended_narrow.DAE" /> <!-- Long left finger-->
      </geometry>
      <material name="black">
        <color rgba="0 0 0 1" />
      </material>
    </visual>
    <collision>
      <origin rpy="1.57 0 0" xyz="0.00 0.02 -0.005" />
      <geometry>
	<cylinder length="0.115" radius="0.01" />
      </geometry>
    </collision>
    <inertial>
      <origin rpy="0 0 0" xyz="0.000000 0.000000 0.000000"/>
      <mass value="0.00094542"/>
      <inertia ixx="2e-08" ixy="0" ixz="0" iyy="3e-08" iyz="0" izz="2e-08"/>
    </inertial>
  </link>

  <!-- gripper base -->
  <link name="${arm}_gripper_base">
    <inertial>
      <mass value="0.28" />
      <origin xyz="0.0014 0 0.024" rpy="0 -0 0" />
      <inertia ixx="0" ixy="0" ixz="0" iyy="0" iyz="0" izz="0" />
    </inertial>
    <visual>
      <origin rpy="1.57 0 3.14" xyz="0 0 0.025"/>
      <geometry>
        <mesh filename="package://baxter_description/meshes/electric_gripper/electric_gripper_base.DAE" scale="1 1 1" />
      </geometry>
      <material name="darkred">
        <color rgba=".5 .1 .1 1"/>
      </material>
    </visual>
    <collision>
      <origin rpy="1.57 0 0" xyz="0.0 0.0 0.025"/>
      <geometry>
        <cylinder length="0.1" radius="0.0275"/>
      </geometry>
    </collision>
  </link>

  <!-- Base of Left end effector -->
  <joint name="${arm}_endpoint" type="fixed">
    <origin xyz="0 0 0.045" rpy="0 -0 0" />
    <axis xyz="0 0 0" />
    <parent link="${arm}_gripper_base" />
    <child link="${arm}_gripper" />
  </joint>

  <!-- Left finger -->
  <joint name="${arm}_gripper_l_finger_joint" type="prismatic">
    <origin rpy="1.57 0 0" xyz="0.0 -0.04 0.035"/>
    <axis xyz="0 0 1"/>
    <parent link="${arm}_gripper"/>
    <child link="${arm}_gripper_l_finger"/>
    <limit effort="20.0" lower="-0.0125" upper="0.0095" velocity="5.0"/> <!-- upper is open -->
    <dynamics damping="0.7" friction="0.0"/>
  </joint>

  <!-- Right finger -->
  <joint name="${arm}_gripper_r_finger_joint" type="prismatic">
    <origin rpy="1.57 0 0" xyz="0.0 0.04 0.035"/>
    <axis xyz="0 0 1"/>
    <parent link="${arm}_gripper"/>
    <child link="${arm}_gripper_r_finger"/>
    <limit effort="20.0" lower="-0.0125" upper="0.0095" velocity="5.0"/> <!-- upper is open -->
    <dynamics damping="0.7" friction="0.0"/>
    <mimic joint="${arm}_gripper_l_finger_joint" offset="0" multiplier="-1" />
  </joint>

</xacro:macro>
</robot>
